Workbook

Sheet Radar
A1: ID_CASO | B1: ORGANISMO | C1: TIPO_NORMA | D1: NUMERO_NORMA | E1: PALABRAS_CLAVE | F1: ACCION_ESPERADA | G1: ESTADO
A2: DESREG-001 | B2: PEN | C2: Resolución | D2: 322/2023 | E2: CERTIFICADO UNICO DE DISCAPACIDAD, DISCAPACIDAD, ACTUALIZACION CUD | F2: Modificación | G2: Inactivo
A3: DESREG-002 | B3: PEN | C3: Decreto | D3: 1187/2012 | E3: CAJA DE AHORRO, BANCO DE LA NACION ARGENTINA, HABERES | F3: Modificación | G3: Inactivo
A4: DESREG-003 | B4: PEN | C4: Decreto | D4: 1191/2012 | E4: AEROLINEAS ARGENTINAS, PASAJES AEREOS, AUSTRAL | F4: Modificación | G4: Inactivo
A5: DESREG-004 | B5: PEN | C5: Decreto | D5: 557/2023 | E5: ARANCEL EXTERNO COMUN, MERCOSUR | F5: Modificación | G5: Inactivo
A6: DESREG-005 | B6: PEN | C6: Decreto | D6: 557/2023 | E6: BIENES DE INFORMATICA Y TELECOMUNICACIONES, ARANCELES DE IMPORTACION | F6: Modificación | G6: Inactivo
A7: DESREG-006 | B7: PEN | C7: Disposición | D7: 21/2023 | E7: TRASBORDO BUQUE A BUQUE, SHIP TO SHIP, TRASBORDO | F7: Modificación | G7: Inactivo
A8: DESREG-007 | B8: PEN | C8: Decreto | D8: 256/2010 | E8: ISLAS MALVINAS, PUERTOS CONTINENTALES, TRANSITO MARITIMO | F8: Modificación | G8: Pendiente
A9: DESREG-008 | B9: PLN | C9: Ley | D9: 27419 | E9: MARINA MERCANTE, ANTIGUEDAD MAXIMA, BUQUES | F9: Derogación | G9: Pendiente
A10: DESREG-009 | B10: PLN | C10: Ley | D10: 19492 | E10: TRIPULACION MINIMA, MARINA MERCANTE, GREMIOS | F10: Modificación | G10: Inactivo
A11: DESREG-010 | B11: PLN | C11: Ley | D11: 27418 | E11: PREFECTURA NAVAL, TALLERES NAVALES, BUQUES, REPARACION | F11: Modificación | G11: Pendiente
A12: DESREG-011 | B12: PEN | C12: Decreto | D12: 2694/1991 | E12: PILOTAJE, PRACTICOS, MANIOBRA SHIP TO SHIP | F12: Modificación | G12: Pendiente
A13: DESREG-012 | B13: PLN | C13: Ley | D13: 14250 | E13: ULTRAACTIVIDAD, CONVENIOS COLECTIVOS | F13: Modificación | G13: Inactivo
A14: DESREG-013 | B14: PLN | C14: Ley | D14: 14250 | E14: CONVENCIONES COLECTIVAS, DESCENTRALIZACION, NEGOCIACION COLECTIVA | F14: Modificación | G14: Inactivo
A15: DESREG-014 | B15: PLN | C15: Ley | D15: 14250 | E15: ARBITRAJE, CONFLICTOS LABORALES, CONVENIOS DE TRABAJO | F15: Modificación | G15: Pendiente
A16: DESREG-015 | B16: PLN | C16: Ley | D16: 12.988/1947 | E16: SEGUROS EN EL EXTERIOR, ASEGURADORAS, ASEGURAR RIESGOS | F16: Modificación | G16: Pendiente
A17: DESREG-016 | B17: PEN | C17: Decreto | D17: 2426/2012 | E17: ASIGNACION DE FRECUENCIAS, FRECUENCIAS, ESPECTRO RADIOELECTRICO | F17: Modificación | G17: Pendiente
A18: DESREG-017 | B18: PEN | C18: Decreto | D18: 915/2010 | E18: PARQUES INDUSTRIALES, REGISTRO NACIONAL DE PARQUES INDUSTRIALES, RENPI | F18: Modificación | G18: Inactivo
A19: DESREG-018 | B19: PEN | C19: Decreto | D19: 68/2022 | E19: APORTES NO REINTEGRABLES, PARQUES INDUSTRIALES, RENPI | F19: Modificación | G19: Inactivo
A20: DESREG-019 | B20: PEN | C20: Resolución | D20: 155/2007 | E20: PRODUCTORES DE PAPA, MINORISTAS, COMPENSACION | F20: Modificación | G20: Inactivo
A21: DESREG-020 | B21: PEN | C21: Resolución | D21: 684/2014 | E21: PRODUCTORES TAMBEROS, TAMBEROS, PRODUCCION LECHERA | F21: Modificación | G21: Inactivo
A22: DESREG-021 | B22: PEN | C22: Resolución | D22: 208/2014 | E22: PRODUCTORES TAMBEROS, REGISTRO DE BENEFICIARIOS, TAMBEROS | F22: Modificación | G22: Inactivo
A23: DESREG-022 | B23: PEN | C23: Resolución | D23: 50/2015 | E23: PATROCINIO JURIDICO GRATUITO, CONFLICTOS DE CONSUMO | F23: Modificación | G23: Inactivo
A24: DESREG-023 | B24: PEN | C24: Resolución | D24: 38718 | E24: PRECIOS MAXIMOS, CADENA DE LA CARNE, CARNE | F24: Derogación | G24: Inactivo
A25: DESREG-024 | B25: PEN | C25: Resolución | D25: 42370 | E25: EL MERCADO EN TU BARRIO, FERIAS AGROALIMENTARIAS | F25: Modificación | G25: Inactivo
A26: DESREG-025 | B26: ENACOM | C26: Resolución | D26: 3597/2016 | E26: PROGRAMA CONECTIVIDAD, AREAS RURALES, TELECOMUNICACIONES | F26: Modificación | G26: Inactivo
A27: DESREG-026 | B27: Secretaría de Comercio | C27: Resolución | D27: 63/2011 | E27: MERCADOS CONCENTRADORES | F27: Modificación | G27: Inactivo
A28: DESREG-027 | B28: Secretaría de Agricultura | C28: Resolución | D28: 1280/2023 | E28: APORTE DE NUTRIENTES, FERTILIZACION NITROGENADA, TRIGO Y MAIZ | F28: Modificación | G28: Inactivo
A29: DESREG-028 | B29: Secretaría de Alimentos, Bioeconomia y Desarrollo Regional | C29: Resolución | D29: 142/2021 | E29: AGROPYMES SUSTENTABLES, BIOECONOMIA | F29: Modificación | G29: Inactivo
A30: DESREG-029 | B30: Secretaría de Calidad en Salud y Secretaría de Alimentos, Bioeconomia y Desarrollo Regional | C30: Resolución | D30: 26/2021 | E30: REGISTRO NACIONAL DE PRODUCTO ALIMENTICIO, CODIGO ALIMENTARIO ARGENTINO, ROTULO | F30: Modificación | G30: Pendiente
A31: DESREG-030 | B31: Ministerio de Desarrollo Productivo | C31: Resolución | D31: 26/2021 | E31: CAPACITACION DE LAS PYMES, AGENCIA DE PROMOCION, PYMES | F31: Modificación | G31: Pendiente
A32: DESREG-031 | B32: Dirección Nacional de Control Agropecuario | C32: Disposición | D32: A9/2019 | E32: COMPRAVENTA DE GRANOS, TIPO DE CAMBIO, DOLAR DIVISA BNA | F32: Modificación | G32: Inactivo
A33: DESREG-032 | B33: ANMAT | C33: Disposición | D33: 1675/2014 | E33: SUPLEMENTOS DIETARIOS, REGISTRO NACIONAL DE ESTABLECIMIENTOS, PRODUCTOS ALIMENTICIOS | F33: Modificación | G33: Pendiente
A34: DESREG-033 | B34: CNV | C34: Resolución | D34: 1025/2024 | E34: PRESTADORES DE SERVICIOS CON ACTIVOS VIRTUALES, ACTIVOS VIRTUALES, CRYPTO | F34: Modificación | G34: Inactivo
A35: DESREG-034 | B35: PLN | C35: Ley | D35: 26854 | E35: MEDIDAS CAUTELARES, CONCESION DE MEDIDAS CAUTELARES | F35: Modificación | G35: Pendiente
A36: DESREG-035 | B36: PLN | C36: Ley | D36: 25344 | E36: EMERGENCIA ECONOMICA, DEMANDA CONTRA EL ESTADO, TRASLADO DE DEMANDA | F36: Modificación | G36: Pendiente
A37: DESREG-036 | B37: PLN | C37: Ley | D37: 25345 | E37: PAGOS EN EFECTIVO, MEDIOS DE PAGO, FACTURACION | F37: Modificación | G37: Pendiente
A38: DESREG-037 | B38: PLN | C38: Ley | D38: 19549 | E38: DOCUMENTO QUE EMITE EL ESTADO, REFORMA PINEIRA, CERTIFICADO DE ANTECEDENTES | F38: Modificación | G38: Pendiente
A39: DESREG-038 | B39: AFIP/ARCA | C39: Resolución | D39: Varios regímenes de información AFIP | E39: REGIMENES DE INFORMACION, REGIMEN DE INFORMACION | F39: Derogación | G39: Pendiente
A40: DESREG-039 | B40: PLN | C40: Ley | D40: 19550 | E40: SOCIEDADES EXTRANJERAS, SOCIEDAD LOCAL, INSCRIPCION REGISTRAL | F40: Modificación | G40: Pendiente
...

Sheet Explicaciones
A1: Seguimiento de Propuesta de Desregulación - Libertad y Progreso | D1: Inactivo | E1: =COUNTIF($E$5:$E$1200,D1)
A2: Plazo Junio 2024 - Mayo 2026. | D2: Pendiente | E2: =COUNTIF($E$5:$E$1200,D2) | F2: =SUM(E1:E2)
A4: Nº | B4: Propuesta | C4: Normativa | D4: Resumen | E4: Resultado
A5: DESREG-001 | C5: Resolución 322/2023 - Actualización CUD | D5: Impone plazos fijos para la actualización del Certificado Único de Discapacidad, lo cual es inadecuado para discapacidades permanentes. | E5: =IF(A5=Radar!A2,Radar!G2,0)
A6: DESREG-002 | C6: Decreto 1187/2012 | D6: El mencionado decreto impone la obligación a todo el personal de las jurisdicciones y entidades de la Administración Pública Nacional de recibir sus sueldos mediante la apertura de Cajas de Ahorro Común en el Banco de la Nación Argentina, entidad autárquica del Estado Nacional. | E6: =IF(A6=Radar!A3,Radar!G3,0)
A7: DESREG-003 | C7: Decreto 1191/2012 | D7: Establece que todas las jurisdicciones y entidades del Sector Público Nacional deben optar por las estatales Aerolíneas Argentinas y Austral para la compra de pasajes aéreos, tanto nacionales como internacionales | E7: =IF(A7=Radar!A4,Radar!G4,0)
A8: DESREG-004 | C8: Decreto 557/2023 | D8: En su anexo V establece incrementos a aranceles por encima del AEC del Mercosur. | E8: =IF(A8=Radar!A5,Radar!G5,0)
A9: DESREG-005 | C9: Decreto 557/2023 | D9: Ampliar la baja de aranceles de importación para Bienes de Informática y Telecomunicaciones al 0%. | E9: =IF(A9=Radar!A6,Radar!G6,0)
A10: DESREG-006 | C10: Disposición 21/2023 - Ship to Ship | D10: Exige contratar un proveedor de servicios para operaciones de trasbordo de buque a buque, encareciendo la operación. | E10: =IF(A10=Radar!A7,Radar!G7,0)
A11: DESREG-007 | C11: Decreto 256/2010 - Tráfico hacia Islas Malvinas | D11: Requiere autorización para tránsito entre puertos continentales y las Islas Malvinas, lo cual limita el libre tránsito. | E11: =IF(A11=Radar!A8,Radar!G8,0)
A12: DESREG-008 | C12: Ley 27.419 - Marina Mercante | D12: Sería conveniente eliminar los límites de antigüedad máxima para los buques y reemplazarlos por estándares estrictos de seguridad, mantenimiento y controles medioambientales. Esta es la solución que adoptan la mayoría de los países, incluyendo la Unión Europa y los EEUU y permiten que un barco más antiguo pueda seguir operando si se cumplen los estándares de seguridad y medioambientales. | E12: =IF(A12=Radar!A9,Radar!G9,0)
A13: DESREG-009 | C13: Decreto Ley 19.492 | D13: De 1944 que establece condicionantes y requisitos de tripulación mínima (Art.11º) que encarecen la operatoria y dan un poder desproporcionado a los gremios. | E13: =IF(A13=Radar!A10,Radar!G10,0)
A14: DESREG-010 | C14: Ley 27.418 | D14: Establece que sólo los talleres o proveedores habilitados por Prefectura (PNA) pueden trabajar en los buques (reparar un motor en el muelle es el doble de costoso que hacerlo en una fábrica del GBA). | E14: =IF(A14=Radar!A11,Radar!G11,0)
A15: DESREG-011 | C15: Decreto 2694/1991 | D15: Convendría actualizar y flexibilizar los requisitos de horarios y duración máxima de los servicios de prácticas para bajar los costos de pilotaje, que hoy son extremadamente elevados (un práctico cobra aprox. 20/25.000 US$ por maniobra de Ship to Ship – duración de no más de 3 días). | E15: =IF(A15=Radar!A12,Radar!G12,0)
A16: DESREG-012 | C16: Ley 14.250 de Convenios de Trabajo | D16: Elimina ultraactividad. | E16: =IF(A16=Radar!A13,Radar!G13,0) | F16: Parcialmente modificadas en Ley de Modernización Laboral
A17: DESREG-013 | C17: Ley 14.250 de Convenios de Trabajo | D17: Descentralización de las convenciones colectivas priorizando los convenios de menor nivel (por ejemplo, a nivel empresa) por sobre los de mayor nivel (por sector o actividad). | E17: =IF(A17=Radar!A14,Radar!G14,0)
A18: DESREG-014 | C18: Ley 14.250 de Convenios de Trabajo | D18: Introducción de un mecanismo de arbitraje oficial que facilite e incentive la resolución de conflictos laborales entre las partes. | E18: =IF(A18=Radar!A15,Radar!G15,0)
A19: DESREG-015 | C19: Ley 12.988/1947 - Seguros en el Exterior | D19: Prohíbe a los argentinos contratar seguros fuera del país, creando un monopolio para aseguradoras locales. | E19: =IF(A19=Radar!A16,Radar!G16,0)
A20: DESREG-016 | C20: Decreto 2426/2012 - Asignación de Frecuencias | D20: Permite asignación de frecuencias directamente a entidades estatales, limitando la competencia privada. | E20: =IF(A20=Radar!A17,Radar!G17,0)
A21: DESREG-017 | C21: Decreto 915/2010 | D21: Crea el Programa Nacional para el Desarrollo de Parques Industriales | E21: =IF(A21=Radar!A18,Radar!G18,0)
A22: DESREG-018 | C22: Decreto 68/2022 | D22: Contempla el otorgamiento de Aportes No Reintegrables para estudios, obras, ampliaciones y proyectos productivos en parques industriales inscriptos en el REGISTRO NACIONAL DE PARQUES INDUSTRIALES (RENPI) creado por el Decreto 915/2010. | E22: =IF(A22=Radar!A19,Radar!G19,0)
A23: DESREG-019 | C23: Resolución 155/2007 - Subsidio a Minoristas | D23: Compensa a minoristas que comercialicen papa de ciertas características, encareciendo la intervención estatal. | E23: =IF(A23=Radar!A20,Radar!G20,0)
A24: DESREG-020 | C24: Resolución 684/2014 - Subsidio a Productores Lecheros | D24: Otorga subsidios a productores tamberos según la producción incremental, incrementando el gasto fiscal discrecional. | E24: =IF(A24=Radar!A21,Radar!G21,0)
A25: DESREG-021 | C25: Resolución 208/2014 | D25: Crea el registro para los beneficiarios de la Resolución 684/2014 | E25: =IF(A25=Radar!A22,Radar!G22,0)
A26: DESREG-022 | C26: Resolución 50/2015 - Patrocinio Jurídico Gratuito | D26: Establece patrocinio gratuito en conflictos de consumo, generando un gasto adicional sin evaluar la situación fiscal. | E26: =IF(A26=Radar!A23,Radar!G23,0)
A27: DESREG-023 | C27: Resolución 1/2006 - Precios Máximos de Carne | D27: Fija precios en toda la cadena de la carne, afectando el libre mercado y distorsionando la oferta. Si bien se ha dejado de aplicar, es conveniente derogarla. | E27: =IF(A27=Radar!A24,Radar!G24,0)
A28: DESREG-024 | C28: Resolución Conjunta 1/2016 - Programa “El Mercado en tu Barrio” | D28: Promueve ferias de productos agroalimentarios, asumiendo funciones que no corresponden al Estado. | E28: =IF(A28=Radar!A25,Radar!G25,0)
A29: DESREG-025 | C29: Resolución 3597/2016 - Programa Conectividad | D29: Subsidia proyectos de conectividad en áreas rurales, aumentando el gasto público en telecomunicaciones. | E29: =IF(A29=Radar!A26,Radar!G26,0) | F29: https://servicios.infoleg.gob.ar/infolegInternet/anexos/420000-424999/421850/norma.htm
A30: DESREG-026 | C30: Resolución 63/2011 - Secretaría de Comercio | D30: Crea un Programa destinado a promover la formación de una red de Mercados concentradores de Interés Nacional. | E30: =IF(A30=Radar!A27,Radar!G27,0)
A31: DESREG-027 | C31: Resolución 1280/2023 - Secretaría de Agricultura | D31: Crea el “Programa de Aporte de Nutrientes 2023” en el ámbito de la Secretaria de Agricultura, Ganadería y Pesca, destinado a brindar apoyo a pequeños productores de trigo y maíz para el incremento de las dosis medias de fertilización nitrogenada. | E31: =IF(A31=Radar!A28,Radar!G28,0)
A32: DESREG-028 | C32: Resolución 142/2021 - Secretaría de Alimentos, Bioeconomia y Desarrollo Regional | D32: Crea el PROGRAMA AGROPyMES SUSTENTABLES en el ámbito de la Secretaría de Alimentos, Bioeconomía y Desarrollo Regional. | E32: =IF(A32=Radar!A29,Radar!G29,0)
A33: DESREG-029 | C33: Resolución Conjunta 26/2021 - Secretaría de Calidad en Salud y Secretaría de Alimentos, Bioeconomia y Desarrollo Regional | D33: Establece la obligación de incorporar el número de Registro Nacional de Producto Alimenticio en el rótulo de todos los productos alimenticios autorizados en el Código Alimentario Argentino. | E33: =IF(A33=Radar!A30,Radar!G30,0)
A34: DESREG-030 | C34: Resolución 26/2021 - Ministerio de Desarrollo Productivo | D34: Crea el Programa "Agencia de Promoción para la Capacitación de las PyMEs" | E34: =IF(A34=Radar!A31,Radar!G31,0) | F34: En vigencia pero sin funcionamiento
A35: DESREG-031 | C35: Disposición 9/2019 - Dirección Nacional de Control Agropecuario | D35: Establece que en los contratos de compraventa de granos con entrega de mercaderías cuyo precio se halle nominado en dólares estadounidenses. Según esta disposición la cancelación —tanto total como parcial— deberá realizarse tomando en cuenta el tipo de cambio dólar divisa del BNA. | E35: =IF(A35=Radar!A32,Radar!G32,0) | F35: Derogada por Resolución 112/2024
A36: DESREG-032 | C36: Disposición 1675/2014 - ANMAT | D36: En su Art.17º establece que las inscripciones en el Registro Nacional de Establecimientos elaboradores de productos alimenticios o de suplementos dietarios tengan una vigencia máxima de 5 años. Tras lo cual, se debe solicitar su renovación. | E36: =IF(A36=Radar!A33,Radar!G33,0)
A37: DESREG-033 | C37: RG 1025/2024 CNV | D37: Propuso regular a los “Prestadores de Servicios con Activos Virtuales” es decir, las empresas que operan con crypto. La resolución es bastante draconiana y trata a cada uno de estos PSAV como si fuese poco menos que un banco. | E37: =IF(A37=Radar!A34,Radar!G34,0) | F37: La RG 1058/2025 modifica, categoriza y simplifica la burocracia. Sigue existiendo el registro por el GAFI, pero se simplifica y normaliza bastante
A38: DESREG-034 | C38: Ley 26.854 - Ley de Medidas Cautelares contra el Estado Nacional | D38: Estableció numerosas restricciones para la concesión de medidas cautelares contra el Estado nacional que en muchos casos la mayoría de la doctrina juzga, con razón, inconstitucionales. | E38: =IF(A38=Radar!A35,Radar!G35,0)
A39: DESREG-035 | C39: Ley 25.344 - Emergencia Económica | D39: En sus artículos 8, 9 y 10, establece un procedimiento por el cual, cuando se inicia una demanda contra el Estado nacional (sus entes descentralizados o incluso empresas con participación estatal), debe adelantarse una copia de la demanda (y de toda la documentación y prueba acompañada) aún antes de que el juez disponga su traslado. Además de ser un trámite innecesario que carga a los particulares con costo y pérdida de tiempo, pone al Estado nacional en una situación de privilegio y ventaja | E39: =IF(A39=Radar!A36,Radar!G36,0)
A40: DESREG-036 | C40: Ley 25.345 - | D40: Priva de efectos entre partes y frente a terceros a los pagos totales o parciales de sumas de dinero en efectivo superiores a 1.000 pesos. | E40: =IF(A40=Radar!A37,Radar!G37,0)
A41: DESREG-037 | C41: Ley 19.549 - Ley de Procedimiento Administrativo | D41: Proponemos una norma similar a la que existe en Chile (reforma Piñeira). El estado no puede pedir un documento que emite el mismo estado (por ejemplo, DNIs, o certificados de no haber cometido crímenes, o certificados de AFIP). | E41: =IF(A41=Radar!A38,Radar!G38,0)
...
